{"uuid": "be63f53b-6eac-4887-81e4-cee0b68dfce2", "children": ["499be33e-7489-43a5-8249-426bb33a0c31"], "befores": [{"name": "driver", "status": "failed", "statusDetails": {"message": "Failed: Failed to initialize Appium driver: Message: An unknown server-side error occurred while processing the command. Original error: Cannot start the 'com.krishivaas' application. Consider checking the driver's troubleshooting documentation. Original error: Cannot start the 'com.krishivaas' application. Consider checking the driver's troubleshooting documentation. Original error: Activity name '.com.krishivaas.app.MainActivity' used to start the app doesn't exist or cannot be launched! Make sure it exists and is a launchable activity\nStacktrace:\nUnknownError: An unknown server-side error occurred while processing the command. Original error: Cannot start the 'com.krishivaas' application. Consider checking the driver's troubleshooting documentation. Original error: Cannot start the 'com.krishivaas' application. Consider checking the driver's troubleshooting documentation. Original error: Activity name '.com.krishivaas.app.MainActivity' used to start the app doesn't exist or cannot be launched! Make sure it exists and is a launchable activity\n    at getResponseForW3CError (C:\\Users\\Pramo\\AppData\\Roaming\\npm\\node_modules\\appium\\node_modules\\@appium\\base-driver\\lib\\protocol\\errors.js:1143:9)\n    at asyncHandler (C:\\Users\\Pramo\\AppData\\Roaming\\npm\\node_modules\\appium\\node_modules\\@appium\\base-driver\\lib\\protocol\\protocol.js:487:57)\n", "trace": "  File \"C:\\Users\\Pramo\\AppData\\Local\\Programs\\Python\\Python312\\Lib\\site-packages\\pluggy\\_callers.py\", line 167, in _multicall\n    teardown.throw(outcome._exception)\n  File \"C:\\Users\\Pramo\\AppData\\Local\\Programs\\Python\\Python312\\Lib\\site-packages\\_pytest\\setuponly.py\", line 36, in pytest_fixture_setup\n    return (yield)\n            ^^^^^\n  File \"C:\\Users\\Pramo\\AppData\\Local\\Programs\\Python\\Python312\\Lib\\site-packages\\pluggy\\_callers.py\", line 103, in _multicall\n    res = hook_impl.function(*args)\n          ^^^^^^^^^^^^^^^^^^^^^^^^^\n  File \"C:\\Users\\Pramo\\AppData\\Local\\Programs\\Python\\Python312\\Lib\\site-packages\\_pytest\\fixtures.py\", line 1195, in pytest_fixture_setup\n    result = call_fixture_func(fixturefunc, request, kwargs)\n             ^^^^^^^^^^^^^^^^^^^^^^^^^^^^^^^^^^^^^^^^^^^^^^^\n  File \"C:\\Users\\Pramo\\AppData\\Local\\Programs\\Python\\Python312\\Lib\\site-packages\\_pytest\\fixtures.py\", line 922, in call_fixture_func\n    fixture_result = next(generator)\n                     ^^^^^^^^^^^^^^^\n  File \"F:\\K_R_F\\conftest.py\", line 39, in driver\n    pytest.fail(f\"Failed to initialize Appium driver: {str(e)}\")\n  File \"C:\\Users\\Pramo\\AppData\\Local\\Programs\\Python\\Python312\\Lib\\site-packages\\_pytest\\outcomes.py\", line 177, in fail\n    raise Failed(msg=reason, pytrace=pytrace)\n"}, "start": 1751969078432, "stop": 1751969087139}], "start": 1751969078432, "stop": 1751969088251}