{"uuid": "71f885a7-8d93-48b9-958a-07dbbf406327", "children": ["8540efdf-b6b3-49a9-9c4a-8f0ff08dca2c"], "befores": [{"name": "driver", "status": "failed", "statusDetails": {"message": "Failed: Failed to initialize Appium driver: Message: An unknown server-side error occurred while processing the command. Original error: The application at 'C:\\Users\\Pramo\\Krishivaas_Farmer_UI_RN(V0.12.34).apk' does not exist or is not accessible\nStacktrace:\nUnknownError: An unknown server-side error occurred while processing the command. Original error: The application at 'C:\\Users\\Pramo\\Krishivaas_Farmer_UI_RN(V0.12.34).apk' does not exist or is not accessible\n    at getResponseForW3CError (C:\\Users\\Pramo\\AppData\\Roaming\\npm\\node_modules\\appium\\node_modules\\@appium\\base-driver\\lib\\protocol\\errors.js:1143:9)\n    at asyncHandler (C:\\Users\\Pramo\\AppData\\Roaming\\npm\\node_modules\\appium\\node_modules\\@appium\\base-driver\\lib\\protocol\\protocol.js:487:57)\n", "trace": "  File \"C:\\Users\\Pramo\\AppData\\Local\\Programs\\Python\\Python312\\Lib\\site-packages\\pluggy\\_callers.py\", line 167, in _multicall\n    teardown.throw(outcome._exception)\n  File \"C:\\Users\\Pramo\\AppData\\Local\\Programs\\Python\\Python312\\Lib\\site-packages\\_pytest\\setuponly.py\", line 36, in pytest_fixture_setup\n    return (yield)\n            ^^^^^\n  File \"C:\\Users\\Pramo\\AppData\\Local\\Programs\\Python\\Python312\\Lib\\site-packages\\pluggy\\_callers.py\", line 103, in _multicall\n    res = hook_impl.function(*args)\n          ^^^^^^^^^^^^^^^^^^^^^^^^^\n  File \"C:\\Users\\Pramo\\AppData\\Local\\Programs\\Python\\Python312\\Lib\\site-packages\\_pytest\\fixtures.py\", line 1140, in pytest_fixture_setup\n    result = call_fixture_func(fixturefunc, request, kwargs)\n             ^^^^^^^^^^^^^^^^^^^^^^^^^^^^^^^^^^^^^^^^^^^^^^^\n  File \"C:\\Users\\Pramo\\AppData\\Local\\Programs\\Python\\Python312\\Lib\\site-packages\\_pytest\\fixtures.py\", line 891, in call_fixture_func\n    fixture_result = next(generator)\n                     ^^^^^^^^^^^^^^^\n  File \"F:\\K_R_F\\conftest.py\", line 39, in driver\n    pytest.fail(f\"Failed to initialize Appium driver: {str(e)}\")\n  File \"C:\\Users\\Pramo\\AppData\\Local\\Programs\\Python\\Python312\\Lib\\site-packages\\_pytest\\outcomes.py\", line 178, in fail\n    raise Failed(msg=reason, pytrace=pytrace)\n"}, "start": 1751968856887, "stop": 1751968863654}], "start": 1751968856887, "stop": 1751968864859}